Workbook

Sheet Report
A2: Project Name | B2: LeafSense - Coffee Leaf Disease Detection System | E2: TOTAL | F2: PASS | G2: FAIL
A3: Stage | B3: Sprint 2 | D3: Status | E3: ='User Management'!C6+'Upload image'!C6+'View Analysis Results'!C6+'Treatment Recommendations'!C6+'Firebase Integration'!C6+'History Analysis'!C6+'Category Management'!C6+'Apply Coupon Code at Checkout'!C6+'Online Marketplace'!C6+'Product Management'!C6+'Search & Filter Products'!C6+'Coupon Management'!C6+'Shopping Cart'!C6+'Edit Profile(Farmer)'!C6+'Edit Profile(Admin) '!C6 -> 159 | F3: ='User Management'!D6+'Upload image'!D6+'View Analysis Results'!D6+'Treatment Recommendations'!D6+'Firebase Integration'!D6+'History Analysis'!D6+'Category Management'!D6+'Apply Coupon Code at Checkout'!D6+'Online Marketplace'!D6+'Product Management'!D6+'Search & Filter Products'!D6+'Coupon Management'!D6+'Shopping Cart'!D6+'Edit Profile(Farmer)'!D6+'Edit Profile(Admin) '!D6 -> 152 | G3: ='User Management'!E6+'Upload image'!E6+'View Analysis Results'!E6+'Treatment Recommendations'!E6+'Firebase Integration'!E6+'History Analysis'!E6+'Category Management'!E6+'Apply Coupon Code at Checkout'!E6+'Online Marketplace'!E6+'Product Management'!E6+'Search & Filter Products'!E6+'Coupon Management'!E6+'Shopping Cart'!E6+'Edit Profile(Farmer)'!E6+'Edit Profile(Admin) '!E6 -> 7
A4: Project Code | D4: Re-test Status | E4: ='User Management'!C8+'Upload image'!C8+'View Analysis Results'!C8+'Treatment Recommendations'!C8+'Firebase Integration'!C8+'History Analysis'!C8+'Category Management'!C8+'Apply Coupon Code at Checkout'!C8+'Online Marketplace'!C8+'Product Management'!C8+'Search & Filter Products'!C8+'Coupon Management'!C8+'Shopping Cart'!C8+'Edit Profile(Farmer)'!C8+'Edit Profile(Admin) '!C8 -> 159 | F4: ='User Management'!D8+'Upload image'!D8+'View Analysis Results'!D8+'Treatment Recommendations'!D8+'Firebase Integration'!D8+'History Analysis'!D8+'Category Management'!D8+'Apply Coupon Code at Checkout'!D8+'Online Marketplace'!D8+'Product Management'!D8+'Search & Filter Products'!D8+'Coupon Management'!D8+'Shopping Cart'!D8+'Edit Profile(Farmer)'!D8+'Edit Profile(Admin) '!D8 -> 153 | G4: ='User Management'!E8+'Upload image'!E8+'View Analysis Results'!E8+'Treatment Recommendations'!E8+'Firebase Integration'!E8+'History Analysis'!E8+'Category Management'!E8+'Apply Coupon Code at Checkout'!E8+'Online Marketplace'!E8+'Product Management'!E8+'Search & Filter Products'!E8+'Coupon Management'!E8+'Shopping Cart'!E8+'Edit Profile(Farmer)'!E8+'Edit Profile(Admin) '!E8 -> 6
A5: Test Environment Setup Description | B5: Web
A7: Tester | B7: Pham Minh Trang
B8: Nguyen Pham Nhat Huy
B9: Duong Quoc Binh
B10: Nguyen Huu Thang
B11: Nguyen Huy Hoang Bao
A12: Test Result | B12: PASS
B13: FAIL
B14: SKIPPED
B15: NOT IMPLEMENTED
A20: No | B20: Testcase ID | C20: Function Name | D20: Sheet Name | E20: Create Date | F20: End Date | G20: Tester
A21: 1 | B21: UM-X | C21: User Management | D21: User Management | E21: Oct 12, 2025 | F21: Oct 12, 2025 | G21: Duong Quoc Binh
A22: 2 | B22: UI-X | C22: Upload Image | D22: Upload Image | E22: Oct 12, 2025 | F22: Oct 12, 2025 | G22: Duong Quoc Binh
A23: 3 | B23: VAR-X | C23: View Analysis Results | D23: View Analysis Results | E23: Oct 12, 2025 | F23: Oct 12, 2025 | G23: Duong Quoc Binh
A24: 4 | B24: TR-X | C24: Treatment Recommendations | D24: Treatment Recommendations | E24: Oct 13, 2025 | F24: Oct 13, 2025 | G24: Duong Quoc Binh
A25: 5 | B25: HA-X | C25: History Analysis | D25: History Analysis | E25: Oct 13, 2025 | F25: Oct 13, 2025 | G25: Nguyen Pham Nhat Huy
A26: 6 | B26: FI-X | C26: Firebase Integration | D26: Firebase Integration | E26: Oct 13, 2025 | F26: Oct 13, 2025 | G26: Duong Quoc Binh
A27: 7 | B27: CTM-X | C27: Category Management | D27: Category Management | E27: Oct 14, 2025 | F27: Oct 14, 2025 | G27: Duong Quoc Binh
A28: 8 | B28: PM-X | C28: Product Management | D28: Product Management | E28: Oct 14, 2025 | F28: Oct 14, 2025 | G28: Duong Quoc Binh
A29: 9 | B29: OM-X | C29: Online Marketplace | D29: Online Marketplace | E29: Oct 14, 2025 | F29: Oct 15, 2025 | G29: Duong Quoc Binh
A30: 10 | B30: SFP-X | C30: Search & Filter Products | D30: Search & Filter Products | E30: Oct 15, 2025 | F30: Oct 15, 2025 | G30: Duong Quoc Binh
A31: 11 | B31: SC-X | C31: Shopping Cart | D31: Shopping Cart | E31: Oct 15, 2025 | F31: Oct 15, 2025 | G31: Duong Quoc Binh
A32: 12 | B32: CPM-X | C32: Coupon Management | D32: Coupon Management | E32: Oct 15, 2025 | F32: Oct 16, 2025 | G32: Duong Quoc Binh
... A35: 15 | B35: EPA-X | C35: Edit Profile(Admin) | D35: Edit Profile(Admin) | E35: Oct 16, 2025 | F35: Oct 17, 2025 | G35: Duong Quoc Binh

Sheet User Management
A1: Module | C1: User Management
A2: Code | C2: UM
A3: Check requirement
A4: Tester | C4: Duong Quoc Binh
A5: Status | C5: TOTAL | D5: PASS | E5: FAIL | F5: Not Implemented | G5: SKIPPED
C6: =COUNTIF($J$12:$J$108, "<>") -> 9 | D6: =COUNTIF($J$12:$J$182, "PASS") -> 8 | E6: =COUNTIF($J$12:$J$182, "FAIL") -> 1 | F6: 0 | G6: 0
A7: Re-test Status | C7: TOTAL | D7: PASS | E7: FAIL | F7: Not Implemented | G7: SKIPPED
C8: =COUNTIF($M$12:$M$482, "<>") -> 9 | D8: =COUNTIF($L$12:$L$211, "PASS") -> 9 | E8: 0 | F8: 0 | G8: 0
A10: STT | B10: Test case ID | C10: Requirements ID | D10: Test case decription | E10: Pre - Condition | F10: Step | G10: Data | H10: Excepted Result | I10: Test Date | J10: Actual Result | K10: Re-test Date | L10: Re-test Result | M10: Assign to
A12: 1 | B12: =CONCATENATE($C$2, " - ", A12) -> UM - 1 | C12: =$C$1 -> User Management | D12: Lock active user successfully | E12: 1. User status is active | F12: 1. Log in to the system by account admin 2. Click Lock → "Ok" | G12: User ID | H12: Status changes to Locked, button changes to Unlock | I12: Oct 15, 2025 | J12: PASS | K12: Oct 20, 2025 | L12: PASS | M12: Duong Quoc Binh
A13: 2 | B13: =CONCATENATE($C$2, " - ", A13) -> UM - 2 | C13: =$C$1 -> User Management | D13: Cancel lock action | E13: 1. User status is active | F13: 1. Log in to the system by account admin 2. Click Lock → " Hủy" | G13: User ID | H13: No changes in status | I13: Oct 15, 2025 | J13: PASS | K13: Oct 20, 2025 | L13: PASS | M13: Duong Quoc Binh
A14: 3 | B14: =CONCATENATE($C$2, " - ", A14) -> UM - 3 | C14: =$C$1 -> User Management | D14: Lock user then refresh the page | E14: 1. User status is active | F14: 1. Log in to the system by account admin 2. Click Lock → "Ok" 3. Refresh page | G14: User ID | H14: Status remains Inactive (stored in DB) | I14: Oct 15, 2025 | J14: PASS | K14: Oct 20, 2025 | L14: PASS | M14: Duong Quoc Binh
A15: 4 | B15: =CONCATENATE($C$2, " - ", A15) -> UM - 4 | C15: =$C$1 -> User Management | D15: Lock user with no internet | E15: 1. User status is active 2. Internet disconnected | F15: 1. Log in to the system by account admin 2. Click Lock → "Ok" | G15: User ID | H15: Show “Network error”, status unchanged | I15: Oct 15, 2025 | J15: FAIL | K15: Oct 20, 2025 | L15: PASS | M15: Duong Quoc Binh
A16: 5 | B16: =CONCATENATE($C$2, " - ", A16) -> UM - 5 | C16: =$C$1 -> User Management | D16: Lock user while on another pagination page | E16: 1. User list > 1 page | F16: 1. Log in to the new page by account admin 2. Click Lock → "Ok" | G16: User ID | H16: Correct user locked on current page | I16: Oct 15, 2025 | J16: PASS | K16: Oct 20, 2025 | L16: PASS | M16: Duong Quoc Binh
A17: 6 | B17: =CONCATENATE($C$2, " - ", A17) -> UM - 6 | C17: =$C$1 -> User Management | D17: Delete user successfully | E17: 1. User is not an admin | F17: 1. Log in to the page by account admin 2. Click Delete → "Ok" | G17: User ID | H17: User removed from list; toast “User deleted successfully” | I17: Oct 15, 2025 | J17: PASS | K17: Oct 20, 2025 | L17: PASS | M17: Duong Quoc Binh
A18: 7 | B18: =CONCATENATE($C$2, " - ", A18) -> UM - 7 | C18: =$C$1 -> User Management | D18: Cancel delete action | E18: 1. User exists | F18: 1. Log in to the page by account admin 2. Click Delete → "Hủy" | G18: User ID | H18: No changes | I18: Oct 15, 2025 | J18: PASS | K18: Oct 20, 2025 | L18: PASS | M18: Duong Quoc Binh
A19: 8 | B19: =CONCATENATE($C$2, " - ", A19) -> UM - 8 | C19: =$C$1 -> User Management | D19: Delete user – API returns server error | E19: 1. Backend 500 error | F19: 1. Log in to the new page by account admin 2. Click Delete → "Ok" | G19: User ID | H19: Show “Failed to delete users”, user not removed | I19: Oct 15, 2025 | J19: PASS | K19: Oct 20, 2025 | L19: PASS | M19: Duong Quoc Binh
A20: 9 | B20: =CONCATENATE($C$2, " - ", A20) -> UM - 9 | C20: =$C$1 -> User Management | D20: Delete user with posts/comments | E20: 1. User has community content | F20: 1. Log in to the page by account admin 2. Click Delete → "Ok" | G20: User ID | I20: Oct 15, 2025 | J20: PASS | K20: Oct 20, 2025 | L20: PASS | M20: Duong Quoc Binh

Sheet Upload image
A1: Module | C1: Upload Imange
A2: Code | C2: UI
A3: Check requirement
A4: Tester | C4: Duong Quoc Binh
A5: Status | C5: TOTAL | D5: PASS | E5: FAIL | F5: Not Implemented | G5: SKIPPED
C6: =COUNTIF($J$12:$J$107, "<>") -> 10 | D6: =COUNTIF($J$12:$J$181, "PASS") -> 8 | E6: =COUNTIF($J$12:$J$181, "FAIL") -> 2 | F6: 0 | G6: 0
A7: Re-test Status | C7: TOTAL | D7: PASS | E7: FAIL | F7: Not Implemented | G7: SKIPPED
C8: =COUNTIF($M$12:$M$481, "<>") -> 10 | D8: =COUNTIF($L$12:$L$210, "PASS") -> 8 | E8: =COUNTIF($J$12:$J$181, "FAIL") -> 2 | F8: 0 | G8: 0
A10: STT | B10: Test case ID | C10: Requirements ID | D10: Test case decription | E10: Pre - Condition | F10: Step | G10: Data | H10: Excepted Result | I10: Test Date | J10: Actual Result | K10: Re-test Date | L10: Re-test Result | M10: Assign to
A12: 1 | B12: =CONCATENATE($C$2, " - ", A12) -> UI - 1 | C12: =$C$1 -> Upload Imange | D12: Upload valid coffee leaf image successfully | E12: 1. User is logged in | F12: 1. Log in to the system 2. Click to " Choose Files" 3. Click to open to upload the image | G12: JPG image (leaf) | H12: Image uploaded successfully | I12: Oct 15, 2025 | J12: PASS | K12: Oct 20, 2025 | L12: PASS | M12: Duong Quoc Binh
A13: 2 | B13: =CONCATENATE($C$2, " - ", A13) -> UI - 2 | C13: =$C$1 -> Upload Imange | D13: Upload PNG image successfully | E13: 1. User is logged in | F13: 1. Log in to the system 2. Click to " Choose Files" 3. Click to open to upload the image | G13: PNG image | H13: Image accepted and uploaded | I13: Oct 15, 2025 | J13: PASS | K13: Oct 20, 2025 | L13: PASS | M13: Duong Quoc Binh
A14: 3 | B14: =CONCATENATE($C$2, " - ", A14) -> UI - 3 | C14: =$C$1 -> Upload Imange | D14: Upload image with large size | E14: 1. User is logged in | F14: 1. Log in to the system 2. Click to " Choose Files" 3. Click to open to upload the PDF file | G14: JPG (10MB) | H14: Image uploaded successfully | I14: Oct 15, 2025 | J14: PASS | K14: Oct 20, 2025 | L14: PASS | M14: Duong Quoc Binh
A15: 4 | B15: =CONCATENATE($C$2, " - ", A15) -> UI - 4 | C15: =$C$1 -> Upload Imange | D15: Upload unsupported file type | E15: 1. User is logged in | F15: 1. Log in to the system 2. Click to " Choose Files" 3. Click to open to upload the image > max size | G15: PDF File | H15: Error message “Unsupported file format” | I15: Oct 15, 2025 | J15: FAIL | K15: Oct 20, 2025 | L15: FAIL | M15: Duong Quoc Binh
A16: 5 | B16: =CONCATENATE($C$2, " - ", A16) -> UI - 5 | C16: =$C$1 -> Upload Imange | D16: Upload image without selecting file | E16: 1. User is logged in | F16: 1. Log in to the system 2. Click to " Choose Files" 3. Click to open to upload without file | G16: None | H16: Nothing happened | I16: Oct 15, 2025 | J16: PASS | K16: Oct 20, 2025 | L16: PASS | M16: Duong Quoc Binh
A17: 6 | B17: =CONCATENATE($C$2, " - ", A17) -> UI - 6 | C17: =$C$1 -> Upload Imange | D17: Upload image when internet disconnected | E17: 1. User is logged in | F17: 1. Log in to the system 2. Click to " Choose Files" 3. Click to open to upload without internet | G17: JPG image | H17: Image uploaded successfully but cannot analysis | I17: Oct 15, 2025 | J17: PASS | K17: Oct 20, 2025 | L17: PASS | M17: Duong Quoc Binh
A18: 7 | B18: =CONCATENATE($C$2, " - ", A18) -> UI - 7 | C18: =$C$1 -> Upload Imange | D18: Upload image and refresh page | E18: 1. User is logged in | F18: 1. Log in to the system 2. Click to " Choose Files" 3. Click to open to upload the image then refresh the page | G18: JPG image | H18: Image still saved and retrievable | I18: Oct 15, 2025 | J18: FAIL | K18: Oct 20, 2025 | L18: FAIL | M18: Duong Quoc Binh
A19: 8 | B19: =CONCATENATE($C$2, " - ", A19) -> UI - 8 | C19: =$C$1 -> Upload Imange | D19: Upload multiple images sequentially | E19: 1. User is logged in | F19: 1. Log in to the system 2. Click to " Choose Files" 3. Click to open to upload the image 1 -> image 2 | G19: 2 JPG image | H19: Each image uploaded successfully | I19: Oct 15, 2025 | J19: PASS | K19: Oct 20, 2025 | L19: PASS | M19: Duong Quoc Binh
A20: 9 | B20: =CONCATENATE($C$2, " - ", A20) -> UI - 9 | C20: =$C$1 -> Upload Imange | D20: Upload image with special characters in filename | E20: 1. User is logged in | F20: 1. Log in to the system 2. Click to " Choose Files" 3. Click to open to upload the image | G20: leaf@#$.jpg | H20: Upload successful, filename handled correctly | I20: Oct 15, 2025 | J20: PASS | K20: Oct 20, 2025 | L20: PASS | M20: Duong Quoc Binh
A21: 10 | B21: =CONCATENATE($C$2, " - ", A21) -> UI - 10 | C21: =$C$1 -> Upload Imange | D21: Upload non-leaf image | E21: 1. User is logged in | F21: 1. Log in to the system 2. Click to " Choose Files" 3. Click to open to upload the image | G21: People image | H21: Image uploaded successfully but cannot analysis | I21: Oct 15, 2025 | J21: PASS | K21: Oct 20, 2025 | L21: PASS | M21: Duong Quoc Binh

Sheet View Analysis Results
A1: Module | C1: View Analysis Results
A2: Code | C2: VAR
A3: Check requirement
A4: Tester | C4: Duong Quoc Binh
A5: Status | C5: TOTAL | D5: PASS | E5: FAIL | F5: Not Implemented | G5: SKIPPED
C6: =COUNTIF($J$12:$J$108, "<>") -> 8 | D6: =COUNTIF($J$12:$J$182, "PASS") -> 7 | E6: =COUNTIF($J$12:$J$182, "FAIL") -> 1 | F6: 0 | G6: 0
A7: Re-test Status | C7: TOTAL | D7: PASS | E7: FAIL | F7: Not Implemented | G7: SKIPPED
C8: =COUNTIF($M$12:$M$482, "<>") -> 8 | D8: =COUNTIF($L$12:$L$211, "PASS") -> 7 | E8: =COUNTIF($L$12:$L$211, "FAIL") -> 1 | F8: 0 | G8: 0
A10: STT | B10: Test case ID | C10: Requirements ID | D10: Test case decription | E10: Pre - Condition | F10: Step | G10: Data | H10: Excepted Result | I10: Test Date | J10: Actual Result | K10: Re-test Date | L10: Re-test Result | M10: Assign to
A12: 1 | B12: =CONCATENATE($C$2, " - ", A12) -> VAR - 1 | C12: =$C$1 -> View Analysis Results | D12: View analysis result after successful image upload | E12: User uploaded image | F12: 1. Click "Analyze 1 image" | G12: Coffee leaf image | H12: Analysis result displayed correctly | I12: Oct 15, 2025 | J12: PASS | K12: Oct 20, 2025 | L12: PASS | M12: Duong Quoc Binh
A13: 2 | B13: =CONCATENATE($C$2, " - ", A13) -> VAR - 2 | C13: =$C$1 -> View Analysis Results | D13: Display disease name correctly | E13: Analysis completed | F13: View Result | G13: Leaf disease detected | H13: Disease name shown | I13: Oct 15, 2025 | J13: PASS | K13: Oct 20, 2025 | L13: PASS | M13: Duong Quoc Binh
A14: 3 | B14: =CONCATENATE($C$2, " - ", A14) -> VAR - 3 | C14: =$C$1 -> View Analysis Results | D14: Display confidence score | E14: Analysis completed | F14: View result | G14: Confidence (%) | H14: Confidence score displayed correctly | I14: Oct 15, 2025 | J14: PASS | K14: Oct 20, 2025 | L14: PASS | M14: Duong Quoc Binh
A15: 4 | B15: =CONCATENATE($C$2, " - ", A15) -> VAR - 4 | C15: =$C$1 -> View Analysis Results | D15: Display healthy leaf result | E15: Healthy image uploaded | F15: View result | G15: Healthy leaf image | H15: Result shows “ No Disease” | I15: Oct 15, 2025 | J15: PASS | K15: Oct 20, 2025 | L15: PASS | M15: Duong Quoc Binh
A16: 5 | B16: =CONCATENATE($C$2, " - ", A16) -> VAR - 5 | C16: =$C$1 -> View Analysis Results | D16: Display analysis image preview | E16: Analysis completed | F16: View result | G16: Uploaded image | H16: Image preview displayed | I16: Oct 15, 2025 | J16: PASS | K16: Oct 20, 2025 | L16: PASS | M16: Duong Quoc Binh
A17: 6 | B17: =CONCATENATE($C$2, " - ", A17) -> VAR - 6 | C17: =$C$1 -> View Analysis Results | D17: View analysis result after successful image upload | E17: Analysis completed | F17: 1. Refresh page | H17: Result still displayed | I17: Oct 15, 2025 | J17: FAIL | K17: Oct 20, 2025 | L17: FAIL | M17: Duong Quoc Binh
A18: 7 | B18: =CONCATENATE($C$2, " - ", A18) -> VAR - 7 | C18: =$C$1 -> View Analysis Results | D18: View the results when uploading a non-coffee leaf image. | E18: Analysis completed | F18: View result | G18: People image | H18: The result returned does not coffee leaves. | I18: Oct 15, 2025 | J18: PASS | K18: Oct 20, 2025 | L18: PASS | M18: Duong Quoc Binh
A19: 8 | B19: =CONCATENATE($C$2, " - ", A19) -> VAR - 8 | C19: =$C$1 -> View Analysis Results | D19: View recommendation after analysis | E19: Analysis completed | F19: View result | G19: Leaf disease detected | H19: Treatment recommendation displayed | I19: Oct 15, 2025 | J19: PASS | K19: Oct 20, 2025 | L19: PASS | M19: Duong Quoc Binh

Sheet Treatment Recommendations
A1: Module | C1: Treatment Recommendations
A2: Code | C2: TR
A3: Check requirement
A4: Tester | C4: Duong Quoc Binh
A5: Status | C5: TOTAL | D5: PASS | E5: FAIL | F5: Not Implemented | G5: SKIPPED
C6: =COUNTIF($J$12:$J$108, "<>") -> 10 | D6: =COUNTIF($J$12:$J$182, "PASS") -> 9 | E6: =COUNTIF($J$12:$J$182, "FAIL") -> 1 | F6: 0 | G6: 0
A7: Re-test Status | C7: TOTAL | D7: PASS | E7: FAIL | F7: Not Implemented | G7: SKIPPED
C8: =COUNTIF($M$12:$M$482, "<>") -> 10 | D8: =COUNTIF($L$12:$L$211, "PASS") -> 9 | E8: =COUNTIF($L$12:$L$182, "FAIL") -> 1 | F8: 0 | G8: 0
A10: STT | B10: Test case ID | C10: Requirements ID | D10: Test case decription | E10: Pre - Condition | F10: Step | G10: Data | H10: Excepted Result | I10: Test Date | J10: Actual Result | K10: Re-test Date | L10: Re-test Result | M10: Assign to
A12: 1 | B12: =CONCATENATE($C$2, " - ", A12) -> TR - 1 | C12: =$C$1 -> Treatment Recommendations | D12: View treatment recommendation after disease detection | E12: Analysis completed with disease detected | F12: 1. Log in to the system 2. Click to " Choose Files" 3. Click to open to upload the image 4. Analysis image | G12: Coffee leaf image (diseased) | H12: Treatment recommendation displayed | I12: Oct 15, 2025 | J12: PASS | K12: Oct 20, 2025 | L12: PASS | M12: Duong Quoc Binh
A13: 2 | B13: =CONCATENATE($C$2, " - ", A13) -> TR - 2 | C13: =$C$1 -> Treatment Recommendations | D13: View treatment recommendation content | E13: Disease detected | F13: View recommendation section | G13: Disease name | H13: Correct recommendation shown for disease | I13: Oct 15, 2025 | J13: PASS | K13: Oct 20, 2025 | L13: PASS | M13: Duong Quoc Binh
A14: 3 | B14: =CONCATENATE($C$2, " - ", A14) -> TR - 3 | C14: =$C$1 -> Treatment Recommendations | D14: View recommendation for healthy leaf | E14: View recommendation for healthy leaf | F14: 1. Log in to the system 2. Click to " Choose Files" 3. Click to open to upload the image 4. Analysis image | G14: Healthy leaf image | H14: Displayed:"Your plant is perfectly healthy! Please continue with your current care routine." | I14: Oct 15, 2025 | J14: PASS | K14: Oct 20, 2025 | L14: PASS | M14: Duong Quoc Binh
A15: 4 | B15: =CONCATENATE($C$2, " - ", A15) -> TR - 4 | C15: =$C$1 -> Treatment Recommendations | D15: Display recommendation with clear steps | E15: Disease detected | F15: Disease detected | G15: Disease detected | H15: Steps shown clearly and completely | I15: Oct 15, 2025 | J15: PASS | K15: Oct 20, 2025 | L15: PASS | M15: Duong Quoc Binh
A16: 5 | B16: =CONCATENATE($C$2, " - ", A16) -> TR - 5 | C16: =$C$1 -> Treatment Recommendations | D16: Display recommended products | E16: Disease detected | F16: View recommendation | G16: Product list | H16: Recommended products displayed | I16: Oct 15, 2025 | J16: FAIL | K16: Oct 20, 2025 | L16: FAIL | M16: Duong Quoc Binh
A17: 6 | B17: =CONCATENATE($C$2, " - ", A17) -> TR - 6 | C17: =$C$1 -> Treatment Recommendations | D17: View recommendation after page refresh | E17: Recommendation exists | F17: Refresh page | G17: Same analysis | H17: Recommendation still displayed | I17: Oct 15, 2025 | J17: PASS | K17: Oct 20, 2025 | L17: PASS | M17: Duong Quoc Binh
A18: 7 | B18: =CONCATENATE($C$2, " - ", A18) -> TR - 7 | C18: =$C$1 -> Treatment Recommendations | D18: View recommendation from history analysis | E18: History record exists | F18: Open history detail | G18: Analysis ID | H18: Recommendation displayed correctly | I18: Oct 15, 2025 | J18: PASS | K18: Oct 20, 2025 | L18: PASS | M18: Duong Quoc Binh
A19: 8 | B19: =CONCATENATE($C$2, " - ", A19) -> TR - 8 | C19: =$C$1 -> Treatment Recommendations | D19: Verify recommendation accuracy per disease | E19: Known disease image | F19: View recommendation | G19: Rust disease | H19: Recommendation matches disease | I19: Oct 15, 2025 | J19: PASS | K19: Oct 20, 2025 | L19: PASS | M19: Duong Quoc Binh
A20: 9 | B20: =CONCATENATE($C$2, " - ", A20) -> TR - 9 | C20: =$C$1 -> Treatment Recommendations | D20: Display dosage and usage instructions | E20: Recommendation available | F20: View recommendation | G20: View recommendation | H20: Dosage and usage displayed correctly | I20: Oct 15, 2025 | J20: PASS | K20: Oct 20, 2025 | L20: PASS | M20: Duong Quoc Binh
A21: 10 | B21: =CONCATENATE($C$2, " - ", A21) -> TR - 10 | C21: =$C$1 -> Treatment Recommendations | D21: Handle missing recommendation data | E21: AI returns no recommendation | F21: View result page | G21: Empty recommendation | H21: Show “Recommendation not available” | I21: Oct 15, 2025 | J21: PASS | K21: Oct 20, 2025 | L21: PASS | M21: Duong Quoc Binh

Sheet Firebase Integration
A1: Module | C1: Firebase Integration
A2: Code | C2: FI
A3: Check requirement
A4: Tester | C4: Duong Quoc Binh
A5: Status | C5: TOTAL | D5: PASS | E5: FAIL | F5: Not Implemented | G5: SKIPPED
C6: =COUNTIF($J$12:$J$106, "<>") -> 6 | D6: =COUNTIF($J$12:$J$180, "PASS") -> 6 | E6: =COUNTIF($J$12:$J$182, "FAIL") -> 0 | F6: 0 | G6: 0
A7: Re-test Status | C7: TOTAL | D7: PASS | E7: FAIL | F7: Not Implemented | G7: SKIPPED
C8: =COUNTIF($M$12:$M$480, "<>") -> 6 | D8: =COUNTIF($L$12:$L$209, "PASS") -> 6 | E8: =COUNTIF($L$12:$L$211, "FAIL") -> 0 | F8: 0 | G8: 0
A10: STT | B10: Test case ID | C10: Requirements ID | D10: Test case decription | E10: Pre - Condition | F10: Step | G10: Data | H10: Excepted Result | I10: Test Date | J10: Actual Result | K10: Re-test Date | L10: Re-test Result | M10: Assign to
A12: 1 | B12: =CONCATENATE($C$2, " - ", A12) -> FI - 1 | C12: Firebase Integration | D12: Upload original image to Firebase after disease analysis | E12: User logged in, analysis completed | F12: 1. Login 2. Upload leaf image 3. Analyze image 4. Check Firebase Storage | G12: Coffee leaf image (diseased) | H12: Original image uploaded to originals/ folder, public URL returned | I12: Oct 16, 2025 | J12: PASS | K12: Oct 21, 2025 | L12: PASS | M12: Duong Quoc Binh
A13: 2 | B13: =CONCATENATE($C$2, " - ", A13) -> FI - 2 | C13: Firebase Integration | D13: Upload user avatar to Firebase | E13: User logged in, profile page opened | F13: 1. Login 2. Go to Settings 3. Click "Upload Avatar" 4. Select image 5. Save | G13: Avatar image (JPG/PNG, <5MB) | H13: Avatar uploaded, public URL saved in user profile | I13: Oct 16, 2025 | J13: PASS | K13: Oct 21, 2026 | L13: PASS | M13: Duong Quoc Binh
A14: 3 | B14: =CONCATENATE($C$2, " - ", A14) -> FI - 3 | C14: Firebase Integration | D14: Upload product image to Firebase (Admin) | E14: Admin logged in, product management opened | F14: 1. Admin login 2. Go to Product Management 3. Click "Add Product" 4. Upload image 5. Save | G14: Product image (JPG/PNG) | H14: Product image uploaded, URL saved in product record | I14: Oct 16, 2025 | J14: PASS | K14: Oct 21, 2027 | L14: PASS | M14: Duong Quoc Binh
A15: 4 | B15: =CONCATENATE($C$2, " - ", A15) -> FI - 4 | C15: Firebase Integration | D15: Upload community post image to Firebase | E15: User logged in, create post page opened | F15: 1. Login 2. Go to Community 3. Click "New Post" 4. Upload image 5. Submit post | G15: Post image (JPG/PNG) | H15: Image uploaded, URL saved in post record | I15: Oct 16, 2025 | J15: PASS | K15: Oct 21, 2028 | L15: PASS | M15: Duong Quoc Binh
A16: 5 | B16: =CONCATENATE($C$2, " - ", A16) -> FI - 5 | C16: Firebase Integration | D16: Handle Firebase upload failure gracefully | E16: User logged in, Firebase service unavailable | F16: 1. Login 2. Upload image 3. Simulate Firebase error | G16: Image file | H16: Error message displayed, system does not crash | I16: Oct 16, 2025 | J16: PASS | K16: Oct 21, 2029 | L16: PASS | M16: Duong Quoc Binh
A17: 6 | B17: =CONCATENATE($C$2, " - ", A17) -> FI - 6 | C17: Firebase Integration | D17: Verify Firebase public URL accessibility | E17: Image uploaded to Firebase | F17: 1. Upload image 2. Get public URL 3. Access URL in browser | G17: Firebase public URL | H17: Image accessible via URL, displays correctly | I17: Oct 16, 2025 | J17: PASS | K17: Oct 21, 2030 | L17: PASS | M17: Duong Quoc Binh

Sheet History Analysis
A1: Module | C1: History Analysis
A2: Code | C2: HA
A3: Check requirement
A4: Tester | C4: Nguyen Pham Nhat Huy
A5: Status | C5: TOTAL | D5: PASS | E5: FAIL | F5: Not Implemented | G5: SKIPPED
C6: =COUNTIF($J$12:$J$105, "<>") -> 10 | D6: =COUNTIF($J$12:$J$179, "PASS") -> 10 | E6: =COUNTIF($J$12:$J$181, "FAIL") -> 0 | F6: 0 | G6: 0
A7: Re-test Status | C7: TOTAL | D7: PASS | E7: FAIL | F7: Not Implemented | G7: SKIPPED
C8: =COUNTIF($M$12:$M$479, "<>") -> 10 | D8: =COUNTIF($L$12:$L$208, "PASS") -> 10 | E8: =COUNTIF($L$12:$L$210, "FAIL") -> 0 | F8: 0 | G8: 0
A10: STT | B10: Test case ID | C10: Requirements ID | D10: Test case decription | E10: Pre - Condition | F10: Step | G10: Data | H10: Excepted Result | I10: Test Date | J10: Actual Result | K10: Re-test Date | L10: Re-test Result | M10: Assign to
A12: 1 | B12: =CONCATENATE($C$2, " - ", A12) -> HA - 1 | C12: History Analysis | D12: View analysis history list | E12: User logged in, has analyzed images | F12: 1. Login 2. Go to History Analysis page | G12: User account with history | H12: List of analyzed images displayed correctly | I12: Oct 16, 2025 | J12: PASS | K12: Oct 21, 2025 | L12: PASS | M12: Nguyen Pham Nhat Huy
A13: 2 | B13: =CONCATENATE($C$2, " - ", A13) -> HA - 2 | C13: History Analysis | D13: View analysis history when no data exists | E13: User logged in, no analysis history | F13: 1. Login 2. Go to History Analysis page | G13: New user account | H13: Message displayed: “No analysis history found” | I13: Oct 16, 2025 | J13: PASS | K13: Oct 21, 2025 | L13: PASS | M13: Nguyen Pham Nhat Huy
A14: 3 | B14: =CONCATENATE($C$2, " - ", A14) -> HA - 3 | C14: History Analysis | D14: View detailed analysis result | E14: User logged in, history exists | F14: 1. Login 2. Go to History Analysis 3. Click one record | G14: Analysis record | H14: Detailed result shown (image, disease, confidence) | I14: Oct 16, 2025 | J14: PASS | K14: Oct 21, 2025 | L14: PASS | M14: Nguyen Pham Nhat Huy
A15: 4 | B15: =CONCATENATE($C$2, " - ", A15) -> HA - 4 | C15: History Analysis | D15: View original image from history | E15: User logged in, image exists in Firebase | F15: 1. Open history detail | G15: Original image URL | H15: Original image displayed correctly | I15: Oct 16, 2025 | J15: PASS | K15: Oct 21, 2025 | L15: PASS | M15: Nguyen Pham Nhat Huy
A16: 5 | B16: =CONCATENATE($C$2, " - ", A16) -> HA - 5 | C16: History Analysis | D16: Verify disease name and confidence display | E16: User logged in, history exists | F16: 1. Open history detail | G16: Disease type, confidence score | H16: Disease name and confidence shown correctly | I16: Oct 16, 2025 | J16: PASS | K16: Oct 21, 2025 | L16: PASS | M16: Nguyen Pham Nhat Huy
A17: 6 | B17: =CONCATENATE($C$2, " - ", A17) -> HA - 6 | C17: History Analysis | D17: Sort history by date (latest first) | E17: User logged in, multiple records exist | F17: 1. Open history page | G17: Multiple history records | H17: Records sorted by newest to oldest | I17: Oct 16, 2025 | J17: PASS | K17: Oct 21, 2025 | L17: PASS | M17: Nguyen Pham Nhat Huy
A18: 7 | B18: =CONCATENATE($C$2, " - ", A18) -> HA - 7 | C18: History Analysis | D18: Filter history by disease type | E18: User logged in, multiple disease records | F18: 1. Open history page 2. Select disease filter | G18: Disease type | H18: Only matching disease records displayed | I18: Oct 16, 2025 | J18: PASS | K18: Oct 21, 2025 | L18: PASS | M18: Nguyen Pham Nhat Huy
A19: 8 | B19: =CONCATENATE($C$2, " - ", A19) -> HA - 8 | C19: History Analysis | D19: Pagination of history list | E19: User logged in, large history data | F19: 1. Open history page 2. Scroll / change page | G19: >10 records | H19: History paginated correctly | I19: Oct 16, 2025 | J19: PASS | K19: Oct 21, 2025 | L19: PASS | M19: Nguyen Pham Nhat Huy
A20: 9 | B20: =CONCATENATE($C$2, " - ", A20) -> HA - 9 | C20: History Analysis | D20: Delete analysis history record | E20: User logged in, history exists | F20: 1. Open history page 2. Delete a record | G20: History record | H20: Record removed from list and database | I20: Oct 16, 2025 | J20: PASS | K20: Oct 21, 2025 | L20: PASS | M20: Nguyen Pham Nhat Huy
A21: 10 | B21: =CONCATENATE($C$2, " - ", A21) -> HA - 10 | C21: History Analysis | D21: Access history without login | E21: User not logged in | F21: 1. Access History Analysis page | G21: None | H21: Redirect to login page | I21: Oct 16, 2025 | J21: PASS | K21: Oct 21, 2025 | L21: PASS | M21: Nguyen Pham Nhat Huy

Sheet Category Management
A1: Module | C1: Category Management
A2: Code | C2: CM
A3: Check requirement
A4: Tester | C4: Duong Quoc Binh
A5: Status | C5: TOTAL | D5: PASS | E5: FAIL | F5: Not Implemented | G5: SKIPPED
C6: =COUNTIF($J$12:$J$105, "<>") -> 7 | D6: =COUNTIF($J$12:$J$179, "PASS") -> 6 | E6: =COUNTIF($J$12:$J$181, "FAIL") -> 1 | F6: 0 | G6: 0
A7: Re-test Status | C7: TOTAL | D7: PASS | E7: FAIL | F7: Not Implemented | G7: SKIPPED
C8: =COUNTIF($M$12:$M$479, "<>") -> 7 | D8: =COUNTIF($L$12:$L$208, "PASS") -> 6 | E8: =COUNTIF($L$12:$L$210, "FAIL") -> 1 | F8: 0 | G8: 0
A10: STT | B10: Test case ID | C10: Requirements ID | D10: Test case decription | E10: Pre - Condition | F10: Step | G10: Data | H10: Excepted Result | I10: Test Date | J10: Actual Result | K10: Re-test Date | L10: Re-test Result | M10: Assign to
A12: 1 | B12: =CONCATENATE($C$2, " - ", A12) -> CM - 1 | C12: Category Management | D12: View category list | E12: Admin logged in | F12: 1. Admin login 2. Go to Category Management | G12: Existing categories | H12: Category list displayed correctly | I12: Oct 16, 2025 | J12: PASS | K12: Oct 21, 2025 | L12: PASS | M12: Duong Quoc Binh
A13: 2 | B13: =CONCATENATE($C$2, " - ", A13) -> CM - 2 | C13: =$C$1 -> Category Management | D13: Add new category | E13: Admin logged in | F13: 1. Go to Category Management 2. Click "Add Category" 3. Enter name 4. Save | G13: Category name | H13: New category added successfully | I13: Oct 16, 2025 | J13: PASS | K13: Oct 21, 2025 | L13: PASS | M13: Duong Quoc Binh
A14: 3 | B14: =CONCATENATE($C$2, " - ", A14) -> CM - 3 | C14: =$C$1 -> Category Management | D14: Add category with empty name | E14: Admin logged in | F14: 1. Click "Add Category" 2. Leave name empty 3. Save | G14: Empty value | H14: Validation message displayed | I14: Oct 16, 2025 | J14: PASS | K14: Oct 21, 2025 | L14: PASS | M14: Duong Quoc Binh
A15: 4 | B15: =CONCATENATE($C$2, " - ", A15) -> CM - 4 | C15: =$C$1 -> Category Management | D15: Add duplicate category name | E15: Admin logged in | F15: 1. Add category with existing name | G15: Duplicate name | H15: Error message shown, category not added | I15: Oct 16, 2025 | J15: FAIL | K15: Oct 21, 2025 | L15: FAIL | M15: Duong Quoc Binh
A16: 5 | B16: =CONCATENATE($C$2, " - ", A16) -> CM - 5 | C16: =$C$1 -> Category Management | D16: Edit category name | E16: Admin logged in, category exists | F16: 1. Click "Edit" 2. Update name 3. Save | G16: Updated category name | H16: Category updated successfully | I16: Oct 16, 2025 | J16: PASS | K16: Oct 21, 2025 | L16: PASS | M16: Duong Quoc Binh
A17: 6 | B17: =CONCATENATE($C$2, " - ", A17) -> CM - 6 | C17: =$C$1 -> Category Management | D17: Edit category with invalid name | E17: Admin logged in, category exists | F17: 1. Edit category 2. Clear name 3. Save | G17: Empty value | H17: Validation error displayed | I17: Oct 16, 2025 | J17: PASS | K17: Oct 21, 2025 | L17: PASS | M17: Duong Quoc Binh
A18: 7 | B18: =CONCATENATE($C$2, " - ", A18) -> CM - 7 | C18: =$C$1 -> Category Management | D18: Delete category not in use | E18: Admin logged in, category exists | F18: 1. Click "Delete" 2. Confirm deletion | G18: Category not linked to product | H18: Category removed successfully | I18: Oct 16, 2025 | J18: PASS | K18: Oct 21, 2025 | L18: PASS | M18: Duong Quoc Binh

Sheet Apply Coupon Code at Checkout
A1: Module | C1: Apply Coupon
A2: Code | C2: AC
A3: Check requirement
A4: Tester | C4: Duong Quoc Binh
A5: Status | C5: TOTAL | D5: PASS | E5: FAIL | F5: Not Implemented | G5: SKIPPED
C6: =COUNTIF($J$12:$J$106, "<>") -> 9 | D6: =COUNTIF($J$12:$J$180, "PASS") -> 9 | E6: =COUNTIF($J$12:$J$182, "FAIL") -> 0 | F6: 0 | G6: 0
A7: Re-test Status | C7: TOTAL | D7: PASS | E7: FAIL | F7: Not Implemented | G7: SKIPPED
C8: =COUNTIF($M$12:$M$480, "<>") -> 9 | D8: =COUNTIF($L$12:$L$209, "PASS") -> 9 | E8: =COUNTIF($L$12:$L$211, "FAIL") -> 0 | F8: 0 | G8: 0
A10: STT | B10: Test case ID | C10: Requirements ID | D10: Test case decription | E10: Pre - Condition | F10: Step | G10: Data | H10: Excepted Result | I10: Test Date | J10: Actual Result | K10: Re-test Date | L10: Re-test Result | M10: Assign to
A12: 1 | B12: =CONCATENATE($C$2, " - ", A12) -> AC - 1 | C12: =C1 -> Apply Coupon | D12: Apply valid coupon code successfully | E12: User logged in, cart has items, checkout page opened | F12: 1. Login 2. Add product to cart 3. Go to Checkout 4. Enter coupon code 5. Click Apply | G12: Valid coupon code | H12: Discount applied, total amount updated | I12: Oct 16, 2025 | J12: PASS | K12: Oct 21, 2025 | L12: PASS | M12: Duong Quoc Binh
A13: 2 | B13: =CONCATENATE($C$2, " - ", A13) -> AC - 2 | C13: =$C$1 -> Apply Coupon | D13: Apply invalid coupon code | E13: User logged in, checkout page opened | F13: 1. Enter invalid coupon 2. Click Apply | G13: Invalid coupon code | H13: Error message displayed, no discount applied | I13: Oct 16, 2025 | J13: PASS | K13: Oct 21, 2025 | L13: PASS | M13: Duong Quoc Binh
A14: 3 | B14: =CONCATENATE($C$2, " - ", A14) -> AC - 3 | C14: =$C$1 -> Apply Coupon | D14: Apply coupon not applicable to cart items | E14: User logged in, cart items not eligible | F14: 1. Enter coupon 2. Click Apply | G14: Coupon code | H14: Message displayed: “Coupon not applicable” | I14: Oct 16, 2025 | J14: PASS | K14: Oct 21, 2025 | L14: PASS | M14: Duong Quoc Binh
A15: 4 | B15: =CONCATENATE($C$2, " - ", A15) -> AC - 4 | C15: =$C$1 -> Apply Coupon | D15: Apply coupon with minimum order amount not met | E15: User logged in, cart total below requirement | F15: 1. Enter coupon 2. Click Apply | G15: Coupon code | H15: Warning shown, discount not applied | I15: Oct 16, 2025 | J15: PASS | K15: Oct 21, 2025 | L15: PASS | M15: Duong Quoc Binh
A16: 5 | B16: =CONCATENATE($C$2, " - ", A16) -> AC - 5 | C16: =$C$1 -> Apply Coupon | D16: Remove applied coupon | E16: User logged in, coupon already applied | F16: 1. Click “Remove coupon” | G16: Applied coupon | H16: Discount removed, total recalculated | I16: Oct 16, 2025 | J16: PASS | K16: Oct 21, 2025 | L16: PASS | M16: Duong Quoc Binh | O16: =N13:O16 -> #REF!
A17: 6 | B17: =CONCATENATE($C$2, " - ", A17) -> AC - 6 | C17: =$C$1 -> Apply Coupon | D17: Apply coupon after changing cart items | E17: User logged in, coupon applied | F17: 1. Change cart quantity 2. Recalculate total | G17: Cart updated | H17: Discount recalculated correctly | I17: Oct 16, 2025 | J17: PASS | K17: Oct 21, 2025 | L17: PASS | M17: Duong Quoc Binh
A18: 7 | B18: =CONCATENATE($C$2, " - ", A18) -> AC - 7 | C18: =$C$1 -> Apply Coupon | D18: Apply coupon with free shipping | E18: User logged in, eligible cart | F18: 1. Enter free shipping coupon | G18: Free shipping coupon | H18: Shipping fee becomes 0 | I18: Oct 16, 2025 | J18: PASS | K18: Oct 21, 2025 | L18: PASS | M18: Duong Quoc Binh
A19: 8 | B19: =CONCATENATE($C$2, " - ", A19) -> AC - 8 | C19: =$C$1 -> Apply Coupon | D19: Apply coupon without login | E19: User not logged in | F19: 1. Go to checkout 2. Enter coupon | G19: Coupon code | H19: System requests login before applying coupon | I19: Oct 16, 2025 | J19: PASS | K19: Oct 21, 2025 | L19: PASS | M19: Duong Quoc Binh
A20: 9 | B20: =CONCATENATE($C$2, " - ", A20) -> AC - 9 | C20: =$C$1 -> Apply Coupon | D20: Apply coupon at order confirmation | E20: User logged in, coupon applied | F20: 1. Place order | G20: Applied coupon | H20: Discount reflected in order summary | I20: Oct 16, 2025 | J20: PASS | K20: Oct 21, 2025 | L20: PASS | M20: Duong Quoc Binh

Sheet Online Marketplace
A1: Module | C1: Online Marketplace
A2: Code | C2: OM
A3: Check requirement
A4: Tester | C4: Duong Quoc Binh
A5: Status | C5: TOTAL | D5: PASS | E5: FAIL | F5: Not Implemented | G5: SKIPPED
C6: =COUNTIF($J$12:$J$106, "<>") -> 15 | D6: =COUNTIF($J$12:$J$180, "PASS") -> 15 | E6: =COUNTIF($J$12:$J$182, "FAIL") -> 0 | F6: 0 | G6: 0
A7: Re-test Status | C7: TOTAL | D7: PASS | E7: FAIL | F7: Not Implemented | G7: SKIPPED
C8: =COUNTIF($M$12:$M$480, "<>") -> 15 | D8: =COUNTIF($L$12:$L$209, "PASS") -> 15 | E8: =COUNTIF($L$12:$L$211, "FAIL") -> 0 | F8: 0 | G8: 0
A10: STT | B10: Test case ID | C10: Requirements ID | D10: Test case decription | E10: Pre - Condition | F10: Step | G10: Data | H10: Excepted Result | I10: Test Date | J10: Actual Result | K10: Re-test Date | L10: Re-test Result | M10: Assign to
A12: 1 | B12: =CONCATENATE($C$2, " - ", A12) -> OM - 1 | C12: =$C$1 -> Online Marketplace | D12: View product list | E12: User is logged in | F12: 1. Open Marketplace | G12: None | H12: Product list is displayed | I12: Oct 17, 2025 | J12: PASS | K12: Oct 22, 2025 | L12: PASS | M12: Duong Quoc Binh
A13: 2 | B13: =CONCATENATE($C$2, " - ", A13) -> OM - 2 | C13: =$C$1 -> Online Marketplace | D13: View product details | E13: Product exists | F13: 1. Click a "Chi Tiết" | G13: Product ID | H13: Product details are shown | I13: Oct 17, 2025 | J13: PASS | K13: Oct 22, 2025 | L13: PASS | M13: Duong Quoc Binh
A14: 3 | B14: =CONCATENATE($C$2, " - ", A14) -> OM - 3 | C14: =$C$1 -> Online Marketplace | D14: Filter products by category | E14: Categories exist | F14: Select category | G14: Category name | H14: Products are filtered correctly | I14: Oct 17, 2025 | J14: PASS | K14: Oct 22, 2025 | L14: PASS | M14: Duong Quoc Binh
A15: 4 | B15: =CONCATENATE($C$2, " - ", A15) -> OM - 4 | C15: =$C$1 -> Online Marketplace | D15: Search product by name | E15: Product exists | F15: Enter keyword | G15: Product name | H15: Matching products are displayed | I15: Oct 17, 2025 | J15: PASS | K15: Oct 22, 2025 | L15: PASS | M15: Duong Quoc Binh
A16: 5 | B16: =CONCATENATE($C$2, " - ", A16) -> OM - 5 | C16: =$C$1 -> Online Marketplace | D16: Search non-existing product | E16: Product exists | F16: Enter invalid keyword: " Batman" | G16: Random text | H16: Display "Không có sản phẩm nào được tìm thấy" | I16: Oct 17, 2025 | J16: PASS | K16: Oct 22, 2025 | L16: PASS | M16: Duong Quoc Binh
A17: 6 | B17: =CONCATENATE($C$2, " - ", A17) -> OM - 6 | C17: =$C$1 -> Online Marketplace | D17: Add product to cart | E17: Product in stock | F17: Click “Add to Cart” | G17: Quantity = 1 | H17: Product is added to cart | I17: Oct 17, 2025 | J17: PASS | K17: Oct 22, 2025 | L17: PASS | M17: Duong Quoc Binh
A18: 7 | B18: =CONCATENATE($C$2, " - ", A18) -> OM - 7 | C18: =$C$1 -> Online Marketplace | D18: Add out-of-stock product | E18: Stock = 0 | F18: N/A | G18: N/A | H18: Out of stock, cannot be added to cart. | I18: Oct 17, 2025 | J18: PASS | K18: Oct 22, 2025 | L18: PASS | M18: Duong Quoc Binh
A19: 8 | B19: =CONCATENATE($C$2, " - ", A19) -> OM - 8 | C19: =$C$1 -> Online Marketplace | D19: Update cart quantity | E19: Product in cart | F19: Change quantity | G19: Quantity = 3 | H19: Cart total updates correctly | I19: Oct 17, 2025 | J19: PASS | K19: Oct 22, 2025 | L19: PASS | M19: Duong Quoc Binh
A20: 9 | B20: =CONCATENATE($C$2, " - ", A20) -> OM - 9 | C20: =$C$1 -> Online Marketplace | D20: Remove product from cart | E20: Product in cart | F20: Click “Clear All” | G20: N/A | H20: Product removed from cart | I20: Oct 17, 2025 | J20: PASS | K20: Oct 22, 2025 | L20: PASS | M20: Duong Quoc Binh
A21: 10 | B21: =CONCATENATE($C$2, " - ", A21) -> OM - 10 | C21: =$C$1 -> Online Marketplace | D21: View shopping cart | E21: Cart not empty | F21: Open cart page | G21: N/A | H21: Cart items & total shown | I21: Oct 17, 2025 | J21: PASS | K21: Oct 22, 2025 | L21: PASS | M21: Duong Quoc Binh
A22: 11 | B22: =CONCATENATE($C$2, " - ", A22) -> OM - 11 | C22: =$C$1 -> Online Marketplace | D22: Checkout with valid information | E22: Cart not empty | F22: Enter shipping info | G22: Valid address, phone | H22: Proceed to payment | I22: Oct 17, 2025 | J22: PASS | K22: Oct 22, 2025 | L22: PASS | M22: Duong Quoc Binh
A23: 12 | B23: =CONCATENATE($C$2, " - ", A23) -> OM - 12 | C23: =$C$1 -> Online Marketplace | D23: Checkout with missing address | E23: Cart not empty | F23: Submit empty address | G23: Address = null | H23: Validation error shown | I23: Oct 17, 2025 | J23: PASS | K23: Oct 22, 2025 | L23: PASS | M23: Duong Quoc Binh
... A26: 15 | B26: =CONCATENATE($C$2, " - ", A26) -> OM - 15 | C26: =$C$1 -> Online Marketplace | D26: View order details | E26: Order exists | F26: Click an order | G26: Order ID | H26: Order details displayed | I26: Oct 17, 2025 | J26: PASS | K26: Oct 22, 2025 | L26: PASS | M26: Duong Quoc Binh

Sheet Product Management
A1: Module | C1: Product Management
A2: Code | C2: PM
A3: Check requirement
A4: Tester | C4: Duong Quoc Binh
A5: Status | C5: TOTAL | D5: PASS | E5: FAIL | F5: Not Implemented | G5: SKIPPED
C6: =COUNTIF($J$12:$J$106, "<>") -> 13 | D6: =COUNTIF($J$12:$J$180, "PASS") -> 12 | E6: =COUNTIF($J$12:$J$182, "FAIL") -> 1 | F6: 0 | G6: 0
A7: Re-test Status | C7: TOTAL | D7: PASS | E7: FAIL | F7: Not Implemented | G7: SKIPPED
C8: =COUNTIF($M$12:$M$480, "<>") -> 13 | D8: =COUNTIF($L$12:$L$209, "PASS") -> 12 | E8: =COUNTIF($L$12:$L$211, "FAIL") -> 1 | F8: 0 | G8: 0
A10: STT | B10: Test case ID | C10: Requirements ID | D10: Test case decription | E10: Pre - Condition | F10: Step | G10: Data | H10: Excepted Result | I10: Test Date | J10: Actual Result | K10: Re-test Date | L10: Re-test Result | M10: Assign to
A12: 1 | B12: =CONCATENATE($C$2, " - ", A12) -> PM - 1 | C12: =$C$1 -> Product Management | D12: View product list | E12: Admin logged in | F12: 1. Open Product Management page | G12: Existing products | H12: Product list displayed | I12: Oct 17, 2025 | J12: PASS | K12: Oct 22, 2025 | L12: PASS | M12: Duong Quoc Binh
A13: 2 | B13: =CONCATENATE($C$2, " - ", A13) -> PM - 2 | C13: =$C$1 -> Product Management | D13: Add new product successfully | E13: Admin logged in | F13: 1. Open Product Management page 2. Click “Add Product” → Fill form → Add | G13: Valid product data | H13: Product added successfully | I13: Oct 17, 2025 | J13: PASS | K13: Oct 22, 2025 | L13: PASS | M13: Duong Quoc Binh
A14: 3 | B14: =CONCATENATE($C$2, " - ", A14) -> PM - 3 | C14: =$C$1 -> Product Management | D14: Add product with missing required fields | E14: Admin logged in | F14: 1. Open Product Management page 2. Click “Add Product” → Submit emty form | G14: Empty fields | H14: Validation message displayed | I14: Oct 17, 2025 | J14: PASS | K14: Oct 22, 2025 | L14: PASS | M14: Duong Quoc Binh
A15: 4 | B15: =CONCATENATE($C$2, " - ", A15) -> PM - 4 | C15: =$C$1 -> Product Management | D15: Add product with invalid price | E15: Add product with invalid price | F15: 1. Open Product Management page 2. Click “Add Product” → Enter negative price | G15: Price = -100 | H15: Error message displayed | I15: Oct 17, 2025 | J15: FAIL | K15: Oct 22, 2025 | L15: FAIL | M15: Duong Quoc Binh
A16: 5 | B16: =CONCATENATE($C$2, " - ", A16) -> PM - 5 | C16: =$C$1 -> Product Management | D16: Update product information | E16: Product exists | F16: 1. Open Product Management page 2. Click “Edit ” → Update | G16: Updated data | H16: Product updated successfully | I16: Oct 17, 2025 | J16: PASS | K16: Oct 22, 2025 | L16: PASS | M16: Duong Quoc Binh
A17: 6 | B17: =CONCATENATE($C$2, " - ", A17) -> PM - 6 | C17: =$C$1 -> Product Management | D17: Update product with invalid data | E17: Product exists | F17: 1. Open Product Management page 2. Click “Edit ” → Update | G17: Invalid data | H17: Error message displayed | I17: Oct 17, 2025 | J17: PASS | K17: Oct 22, 2025 | L17: PASS | M17: Duong Quoc Binh
A18: 7 | B18: =CONCATENATE($C$2, " - ", A18) -> PM - 7 | C18: =$C$1 -> Product Management | D18: Delete product successfully | E18: Product exists | F18: 1. Open Product Management page 2. Click “Delete ” → Confirm | G18: Product ID | H18: Product removed from list | I18: Oct 17, 2025 | J18: PASS | K18: Oct 22, 2025 | L18: PASS | M18: Duong Quoc Binh
A19: 8 | B19: =CONCATENATE($C$2, " - ", A19) -> PM - 8 | C19: =$C$1 -> Product Management | D19: Cancel delete product | E19: Cancel delete product | F19: 1. Open Product Management page 2. Click “Delete ” → Cancel | G19: Product ID | H19: Product not deleted | I19: Oct 17, 2025 | J19: PASS | K19: Oct 22, 2025 | L19: PASS | M19: Duong Quoc Binh
A20: 9 | B20: =CONCATENATE($C$2, " - ", A20) -> PM - 9 | C20: =$C$1 -> Product Management | D20: Search product by name | E20: Products exist | F20: Enter keyword "Kali" | G20: Product name | H20: Matching products displayed | I20: Oct 17, 2025 | J20: PASS | K20: Oct 22, 2025 | L20: PASS | M20: Duong Quoc Binh
A21: 10 | B21: =CONCATENATE($C$2, " - ", A21) -> PM - 10 | C21: =$C$1 -> Product Management | D21: Search product with no result | E21: Products exist | F21: Enter invalid keyword " Batman" | G21: Random text | H21: “No product found” displayed | I21: Oct 17, 2025 | J21: PASS | K21: Oct 22, 2025 | L21: PASS | M21: Duong Quoc Binh
A22: 11 | B22: =CONCATENATE($C$2, " - ", A22) -> PM - 11 | C22: =$C$1 -> Product Management | D22: Upload product image successfully | E22: Admin logged in | F22: Upload valid image | G22: JPG/PNG | H22: Image uploaded & displayed | I22: Oct 17, 2025 | J22: PASS | K22: Oct 22, 2025 | L22: PASS | M22: Duong Quoc Binh
A23: 12 | B23: =CONCATENATE($C$2, " - ", A23) -> PM - 12 | C23: =$C$1 -> Product Management | D23: Upload invalid product image | E23: Admin logged in | F23: Upload invalid file | G23: PDF/EXE | H23: Error message displayed | I23: Oct 17, 2025 | J23: PASS | K23: Oct 22, 2025 | L23: PASS | M23: Duong Quoc Binh
A24: 13 | B24: =CONCATENATE($C$2, " - ", A24) -> PM - 13 | C24: =$C$1 -> Product Management | D24: View product list pagination | E24: Many products exist | F24: Navigate pages | G24: Page number | H24: Correct products shown | I24: Oct 17, 2025 | J24: PASS | K24: Oct 22, 2025 | L24: PASS | M24: Duong Quoc Binh

Sheet Search & Filter Products
A1: Module | C1: Search & Filter Products
A2: Code | C2: SFP
A3: Check requirement
A4: Tester | C4: Duong Quoc Binh
A5: Status | C5: TOTAL | D5: PASS | E5: FAIL | F5: Not Implemented | G5: SKIPPED
C6: =COUNTIF($J$12:$J$106, "<>") -> 10 | D6: =COUNTIF($J$12:$J$180, "PASS") -> 10 | E6: =COUNTIF($J$12:$J$182, "FAIL") -> 0 | F6: 0 | G6: 0
A7: Re-test Status | C7: TOTAL | D7: PASS | E7: FAIL | F7: Not Implemented | G7: SKIPPED
C8: =COUNTIF($M$12:$M$480, "<>") -> 10 | D8: =COUNTIF($L$12:$L$209, "PASS") -> 10 | E8: =COUNTIF($L$12:$L$211, "FAIL") -> 0 | F8: 0 | G8: 0
A10: STT | B10: Test case ID | C10: Requirements ID | D10: Test case decription | E10: Pre - Condition | F10: Step | G10: Data | H10: Excepted Result | I10: Test Date | J10: Actual Result | K10: Re-test Date | L10: Re-test Result | M10: Assign to
A12: 1 | B12: =CONCATENATE($C$2, " - ", A12) -> SFP - 1 | C12: =$C$1 -> Search & Filter Products | D12: Search product by valid name | E12: Products exist | F12: Enter keyword in search box | G12: "Kali" | H12: Matching products are displayed | I12: Oct 17, 2025 | J12: PASS | K12: Oct 22, 2025 | L12: PASS | M12: Duong Quoc Binh
A13: 2 | B13: =CONCATENATE($C$2, " - ", A13) -> SFP - 2 | C13: =$C$1 -> Search & Filter Products | D13: Search product by partial name | E13: Products exist | F13: Enter partial keyword | G13: "NPK" | H13: Related products are displayed | I13: Oct 17, 2025 | J13: PASS | K13: Oct 22, 2025 | L13: PASS | M13: Duong Quoc Binh
A14: 3 | B14: =CONCATENATE($C$2, " - ", A14) -> SFP - 3 | C14: =$C$1 -> Search & Filter Products | D14: Search product with uppercase characters | E14: Products exist | F14: Enter uppercase keyword | G14: "KALI" | H14: Products are displayed | I14: Oct 17, 2025 | J14: PASS | K14: Oct 22, 2025 | L14: PASS | M14: Duong Quoc Binh
A15: 4 | B15: =CONCATENATE($C$2, " - ", A15) -> SFP - 4 | C15: =$C$1 -> Search & Filter Products | D15: Search product with lowercase characters | E15: Products exist | F15: Enter lowercase keyword | G15: "kali" | H15: Products are displayed | I15: Oct 17, 2025 | J15: PASS | K15: Oct 22, 2025 | L15: PASS | M15: Duong Quoc Binh
A16: 5 | B16: =CONCATENATE($C$2, " - ", A16) -> SFP - 5 | C16: =$C$1 -> Search & Filter Products | D16: Search product with special characters | E16: Products exist | F16: Enter special characters | G16: “@@@###” | H16: No products found message | I16: Oct 17, 2025 | J16: PASS | K16: Oct 22, 2025 | L16: PASS | M16: Duong Quoc Binh
A17: 6 | B17: =CONCATENATE($C$2, " - ", A17) -> SFP - 6 | C17: =$C$1 -> Search & Filter Products | D17: Filter products by category | E17: Categories exist | F17: Select category | G17: “Pesticides” | H17: Products of selected category shown | I17: Oct 17, 2025 | J17: PASS | K17: Oct 22, 2025 | L17: PASS | M17: Duong Quoc Binh
A18: 7 | B18: =CONCATENATE($C$2, " - ", A18) -> SFP - 7 | C18: =$C$1 -> Search & Filter Products | D18: Filter products by empty category | E18: Categories exist | F18: Select category with no products | G18: “Tools” | H18: No products found message | I18: Oct 17, 2025 | J18: PASS | K18: Oct 22, 2025 | L18: PASS | M18: Duong Quoc Binh
A19: 8 | B19: =CONCATENATE($C$2, " - ", A19) -> SFP - 8 | C19: =$C$1 -> Search & Filter Products | D19: Filter products by price range | E19: Products exist | F19: Set price range | G19: 100,000 – 300,000 VND | H19: Products within range shown | I19: Oct 17, 2025 | J19: PASS | K19: Oct 22, 2025 | L19: PASS | M19: Duong Quoc Binh
A20: 9 | B20: =CONCATENATE($C$2, " - ", A20) -> SFP - 9 | C20: =$C$1 -> Search & Filter Products | D20: Combine search and category filter | E20: Products exist | F20: Search + select category | G20: Keyword + category | H20: Results match both conditions | I20: Oct 17, 2025 | J20: PASS | K20: Oct 22, 2025 | L20: PASS | M20: Duong Quoc Binh
A21: 10 | B21: =CONCATENATE($C$2, " - ", A21) -> SFP - 10 | C21: =$C$1 -> Search & Filter Products | D21: Search with empty keyword | E21: Products exist | F21: Leave search empty | G21: Empty input | H21: All products are displayed | I21: Oct 17, 2025 | J21: PASS | K21: Oct 22, 2025 | L21: PASS | M21: Duong Quoc Binh

Sheet Coupon Management
A1: Module | C1: Coupon Management
A2: Code | C2: CPM
A3: Check requirement
A4: Tester | C4: Duong Quoc Binh
A5: Status | C5: TOTAL | D5: PASS | E5: FAIL | F5: Not Implemented | G5: SKIPPED
C6: =COUNTIF($J$12:$J$106, "<>") -> 20 | D6: =COUNTIF($J$12:$J$180, "PASS") -> 20 | E6: =COUNTIF($J$12:$J$182, "FAIL") -> 0 | F6: 0 | G6: 0
A7: Re-test Status | C7: TOTAL | D7: PASS | E7: FAIL | F7: Not Implemented | G7: SKIPPED
C8: =COUNTIF($M$12:$M$480, "<>") -> 20 | D8: =COUNTIF($L$12:$L$209, "PASS") -> 20 | E8: =COUNTIF($L$12:$L$211, "FAIL") -> 0 | F8: 0 | G8: 0
A10: STT | B10: Test case ID | C10: Requirements ID | D10: Test case decription | E10: Pre - Condition | F10: Step | G10: Data | H10: Excepted Result | I10: Test Date | J10: Actual Result | K10: Re-test Date | L10: Re-test Result | M10: Assign to
A12: 1 | B12: =CONCATENATE($C$2, " - ", A12) -> CPM - 1 | C12: =$C$1 -> Coupon Management | D12: View coupon list | E12: Admin logged in | F12: Open Coupon Management page | G12: N/A | H12: All coupons are displayed | I12: Oct 17, 2025 | J12: PASS | K12: Oct 21, 2025 | L12: PASS | M12: Duong Quoc Binh
A13: 2 | B13: =CONCATENATE($C$2, " - ", A13) -> CPM - 2 | C13: =$C$1 -> Coupon Management | D13: Create new coupon with valid data | E13: Admin logged in | F13: Click “Add Coupon” and submit form | G13: Code=SAVE10, 10% | H13: Coupon created successfully | I13: Oct 17, 2025 | J13: PASS | K13: Oct 21, 2025 | L13: PASS | M13: Duong Quoc Binh
A14: 3 | B14: =CONCATENATE($C$2, " - ", A14) -> CPM - 3 | C14: =$C$1 -> Coupon Management | D14: Create coupon with duplicate code | E14: Coupon code exists | F14: Create coupon | G14: Code=SAVE10 | H14: Displayed "Failed to add coupon | I14: Oct 17, 2025 | J14: PASS | K14: Oct 21, 2025 | L14: PASS | M14: Duong Quoc Binh
A15: 4 | B15: =CONCATENATE($C$2, " - ", A15) -> CPM - 4 | C15: =$C$1 -> Coupon Management | D15: Create coupon with missing required fields | E15: Admin logged in | F15: Submit empty form | G15: Empty fields | H15: Validation error displayed | I15: Oct 17, 2025 | J15: PASS | K15: Oct 21, 2025 | L15: PASS | M15: Duong Quoc Binh
A16: 5 | B16: =CONCATENATE($C$2, " - ", A16) -> CPM - 5 | C16: =$C$1 -> Coupon Management | D16: Create coupon with invalid discount value | E16: Admin logged in | F16: Enter discount > 100% | G16: Discount=150% | H16: Validation error displayed | I16: Oct 17, 2025 | J16: PASS | K16: Oct 21, 2025 | L16: PASS | M16: Duong Quoc Binh
A17: 6 | B17: =CONCATENATE($C$2, " - ", A17) -> CPM - 6 | C17: =$C$1 -> Coupon Management | D17: Create coupon with past expiration date | E17: Admin logged in | F17: Set expired date | G17: Date > today | H17: Coupon created successfully | I17: Oct 17, 2025 | J17: PASS | K17: Oct 21, 2025 | L17: PASS | M17: Duong Quoc Binh
A18: 7 | B18: =CONCATENATE($C$2, " - ", A18) -> CPM - 7 | C18: =$C$1 -> Coupon Management | D18: Update coupon information | E18: Coupon exists | F18: Edit coupon | G18: New discount | H18: Coupon updated successfully | I18: Oct 17, 2025 | J18: PASS | K18: Oct 21, 2025 | L18: PASS | M18: Duong Quoc Binh
A19: 8 | B19: =CONCATENATE($C$2, " - ", A19) -> CPM - 8 | C19: =$C$1 -> Coupon Management | D19: Disable active coupon | E19: Coupon active | F19: Set status = inactive | G19: Inactive | H19: Coupon cannot be used | I19: Oct 17, 2025 | J19: PASS | K19: Oct 21, 2025 | L19: PASS | M19: Duong Quoc Binh
A20: 9 | B20: =CONCATENATE($C$2, " - ", A20) -> CPM - 9 | C20: =$C$1 -> Coupon Management | D20: Delete coupon | E20: Coupon exists | F20: Delete coupon | G20: Coupon ID | H20: Coupon removed | I20: Oct 17, 2025 | J20: PASS | K20: Oct 21, 2025 | L20: PASS | M20: Duong Quoc Binh
A21: 10 | B21: =CONCATENATE($C$2, " - ", A21) -> CPM - 10 | C21: =$C$1 -> Coupon Management | D21: Search coupon by code | E21: Coupons exist | F21: Enter coupon code | G21: LEAF10 | H21: Matching coupon displayed | I21: Oct 17, 2025 | J21: PASS | K21: Oct 21, 2025 | L21: PASS | M21: Duong Quoc Binh
A22: 11 | B22: =CONCATENATE($C$2, " - ", A22) -> CPM - 11 | C22: =$C$1 -> Coupon Management | D22: Verify admin can create a new coupon successfully | E22: 1. Admin logged in. 2. Coupon management page accessible. 3. “Create coupon” button visible. | F22: 1. Go to Coupon Management. 2. Click “Create Coupon”. 3. Enter coupon | G22: Code: SAVE10, Discount: 10%, Validity: Today–Next 7 days | H22: Coupon appears in coupon list with correct information. | I22: Oct 17, 2025 | J22: PASS | K22: Oct 21, 2025 | L22: PASS | M22: Duong Quoc Binh
A23: 12 | B23: =CONCATENATE($C$2, " - ", A23) -> CPM - 12 | C23: =$C$1 -> Coupon Management | D23: Verify admin cannot create a coupon with a duplicate code | E23: 1. Admin logged in. 2. A coupon with code “SAVE10” already exists. | F23: 1. Click “Create Coupon”. 2. Enter coupon code “SAVE10”. 3. Fill other fields. 4. Click “Save”. | G23: Code = SAVE10 | H23: System shows error “Coupon code already exists”. Coupon not created. | I23: Oct 17, 2025 | J23: PASS | K23: Oct 21, 2025 | L23: PASS | M23: Duong Quoc Binh
... A31: 20 | B31: =CONCATENATE($C$2, " - ", A31) -> CPM - 20 | C31: =$C$1 -> Coupon Management | D31: Verify invalid coupon code format is rejected | E31: 1. User logged in. 2. Checkout page open.2. User has already used it in past. | F31: 1. Enter invalid coupon (e.g., special characters). 2. Click “Apply Coupon”. | G31: Code: “@$%!?” | H31: System shows “Invalid coupon format”. | I31: Oct 17, 2025 | J31: PASS | K31: Oct 21, 2025 | L31: PASS | M31: Duong Quoc Binh

Sheet Shopping Cart
A1: Module | C1: Shopping Cart
A2: Code | C2: SC
A3: Check requirement
A4: Tester | C4: Duong Quoc Binh
A5: Status | C5: TOTAL | D5: PASS | E5: FAIL | F5: Not Implemented | G5: SKIPPED
C6: =COUNTIF($J$12:$J$106, "<>") -> 9 | D6: =COUNTIF($J$12:$J$180, "PASS") -> 9 | E6: =COUNTIF($J$12:$J$182, "FAIL") -> 0 | F6: 0 | G6: 0
A7: Re-test Status | C7: TOTAL | D7: PASS | E7: FAIL | F7: Not Implemented | G7: SKIPPED
C8: =COUNTIF($M$12:$M$480, "<>") -> 9 | D8: =COUNTIF($L$12:$L$209, "PASS") -> 9 | E8: =COUNTIF($L$12:$L$211, "FAIL") -> 0 | F8: 0 | G8: 0
A10: STT | B10: Test case ID | C10: Requirements ID | D10: Test case decription | E10: Pre - Condition | F10: Step | G10: Data | H10: Excepted Result | I10: Test Date | J10: Actual Result | K10: Re-test Date | L10: Re-test Result | M10: Assign to
A12: 1 | B12: =CONCATENATE($C$2, " - ", A12) -> SC - 1 | C12: =$C$1 -> Shopping Cart | D12: Add product to shopping cart | E12: 1. User logged in 2. Product in stock | F12: Click “Add to Cart” | G12: Product ID | H12: Product added to cart | I12: Oct 18, 2025 | J12: PASS | K12: Oct 22, 2025 | L12: PASS | M12: Duong Quoc Binh
A13: 2 | B13: =CONCATENATE($C$2, " - ", A13) -> SC - 2 | C13: =$C$1 -> Shopping Cart | D13: Add multiple products to cart | E13: 1. User logged in 2. Product in stock | F13: Add different products | G13: Product ID | H13: All products added to cart | I13: Oct 18, 2025 | J13: PASS | K13: Oct 22, 2025 | L13: PASS | M13: Duong Quoc Binh
A14: 3 | B14: =CONCATENATE($C$2, " - ", A14) -> SC - 3 | C14: =$C$1 -> Shopping Cart | D14: Increase product quantity | E14: Product already in cart | F14: ncrease quantity | G14: Quantity = 3 | H14: Quantity updated correctly | I14: Oct 18, 2025 | J14: PASS | K14: Oct 22, 2025 | L14: PASS | M14: Duong Quoc Binh
A15: 4 | B15: =CONCATENATE($C$2, " - ", A15) -> SC - 4 | C15: =$C$1 -> Shopping Cart | D15: Decrease product quantity | E15: Product already in cart | F15: Decrease quantity | G15: Quantity = 1 | H15: Quantity updated correctly | I15: Oct 18, 2025 | J15: PASS | K15: Oct 22, 2025 | L15: PASS | M15: Duong Quoc Binh
A16: 5 | B16: =CONCATENATE($C$2, " - ", A16) -> SC - 5 | C16: =$C$1 -> Shopping Cart | D16: Remove product from cart | E16: Product in cart | F16: Click “Clear All” | G16: Product ID | H16: Product removed from cart | I16: Oct 18, 2025 | J16: PASS | K16: Oct 22, 2025 | L16: PASS | M16: Duong Quoc Binh
A17: 6 | B17: =CONCATENATE($C$2, " - ", A17) -> SC - 6 | C17: =$C$1 -> Shopping Cart | D17: View shopping cart | E17: Cart not empty | F17: Open cart page | G17: N/A | H17: Cart items and total shown | I17: Oct 18, 2025 | J17: PASS | K17: Oct 22, 2025 | L17: PASS | M17: Duong Quoc Binh
A18: 7 | B18: =CONCATENATE($C$2, " - ", A18) -> SC - 7 | D18: Cart total price calculation | E18: Multiple products in cart | F18: View cart | G18: Prices & quantities | H18: Total calculated correctly | I18: Oct 18, 2025 | J18: PASS | K18: Oct 22, 2025 | L18: PASS | M18: Duong Quoc Binh
